<?xml version="1.0"?>
<robot name="diff_drive" xmlns:xacro="http://www.ros.org/wiki/xacro">

  <!-- Xacro properties -->
  <xacro:property name="wheel_radius" value="0.15"/>  <!-- 30cm diameter -->
  <xacro:property name="wheel_thickness" value="0.05"/> <!-- 5cm thick -->
  <xacro:property name="caster_radius" value="0.075"/>   <!-- 15cm diameter -->

  <!-- Materials -->
  <material name="black">
    <color rgba="0 0 0 1"/>
  </material>
  <material name="gray">
    <color rgba="0.5 0.5 0.5 1"/>
  </material>
  <material name="blue">
    <color rgba="0 0 1 1"/>
  </material>
  <material name="white">
    <color rgba="1 1 1 1"/>
  </material>

  <!-- Base -->
  <link name="base_link">
    <visual>
      <origin xyz="0 0 0.3" rpy="0 0 0"/>
      <geometry>
        <box size="0.8 0.4 0.2"/>
      </geometry>
      <material name="blue"/>
    </visual>
    <collision>
      <origin xyz="0 0 0.3" rpy="0 0 0"/>
      <geometry>
        <box size="0.8 0.4 0.2"/>
      </geometry> 
    </collision>
    <inertial>
      <mass value="5.0"/>
      <inertia ixx="0.083" ixy="0.0" ixz="0.0"
               iyy="0.183" iyz="0.0"
               izz="0.233"/>
    </inertial>
  </link>

  <link name="base_footprint"/>
  <joint name="base_footprint_joint" type='fixed'>
    <parent link='base_footprint'/>
    <child link='base_link'/>
    <origin xyz='0 0 0.05' rpy='0 0 0'/>
  </joint>

  <!-- Left wheel -->
  <link name="left_wheel_link">
    <visual>
      <geometry>
        <cylinder radius="${wheel_radius}" length="${wheel_thickness}"/>
      </geometry>
      <material name="black"/>
    </visual>
    <collision>
      <geometry>
        <cylinder radius="${wheel_radius}" length="${wheel_thickness}"/>
      </geometry>
    </collision>
    <inertial>
      <mass value="0.5"/>
      <inertia ixx="0.003" ixy="0.0" ixz="0.0"
               iyy="0.003" iyz="0.0"
               izz="0.002"/>
    </inertial>
  </link>

  <joint name="left_wheel_joint" type="continuous">
    <parent link="base_link"/>
    <child link="left_wheel_link"/>
    <origin xyz="-0.15 -0.24 0.15" rpy="1.5708 0 0"/>
    <axis xyz="0 0 1"/>
    <limit effort="10.0" velocity="20.0"/>
    <dynamics damping="0.1" friction="0.005"/>
  </joint>

  <!-- Right wheel -->
  <link name="right_wheel_link">
    <visual>
      <geometry>
        <cylinder radius="${wheel_radius}" length="${wheel_thickness}"/>
      </geometry>
      <material name="black"/>
    </visual>
    <collision>
      <geometry>
        <cylinder radius="${wheel_radius}" length="${wheel_thickness}"/>
      </geometry>
    </collision>
    <inertial>
      <mass value="0.5"/>
      <inertia ixx="0.003" ixy="0.0" ixz="0.0"
               iyy="0.003" iyz="0.0"
               izz="0.002"/>
    </inertial>
  </link>

  <joint name="right_wheel_joint" type="continuous">
    <parent link="base_link"/>
    <child link="right_wheel_link"/>
    <origin xyz="-0.15 0.24 0.15" rpy="1.5708 0 0"/>
    <axis xyz="0 0 1"/>
    <limit effort="10.0" velocity="20.0"/>
    <dynamics damping="0.1" friction="0.005"/>
  </joint>

  <!-- Caster wheel -->
  <link name="caster_wheel">
    <visual>
      <geometry>
        <sphere radius="${caster_radius}"/>
      </geometry>
      <material name="gray"/>
    </visual>
    <collision>
      <geometry>
        <sphere radius="${caster_radius}"/>
      </geometry>
    </collision>
    <inertial>
      <mass value="0.2"/>
      <inertia ixx="0.001" ixy="0.0" ixz="0.0"
               iyy="0.001" iyz="0.0"
               izz="0.001"/>
    </inertial>
  </link>

  <joint name="caster_wheel_joint" type="fixed">
    <parent link="base_link"/>
    <child link="caster_wheel"/>
    <origin xyz="0.3 0 0.075" rpy="0 0 0"/> <!-- touches ground -->
  </joint>

  <!-- Lidar link -->
  <link name="lidar_link">
    <visual>
      <geometry>
        <cylinder radius="0.1" length="0.05"/>
      </geometry>
      <origin xyz="0 0 0" rpy="0 0 0"/>
      <material name="white"/>
    </visual>
    <collision>
      <geometry>
        <cylinder radius="0.1" length="0.05"/>
      </geometry>
    </collision>
    <inertial>
      <mass value="0.114"/>
      <inertia ixx="0.001" ixy="0.0" ixz="0.0"
               iyy="0.001" iyz="0.0"
               izz="0.001"/>
    </inertial>
  </link>

  <joint name="lidar_base_joint" type="fixed">
    <parent link="base_link"/>
    <child link="lidar_link"/>
    <origin xyz="0 0 0.45" rpy="0 0 0"/>
  </joint>

  <!-- Lidar Sensor -->
  <gazebo reference="lidar_link">
    <sensor name='laser' type='ray'>
      <pose>0 0 0 0 0 0</pose>
      <visualize>true</visualize>
      <update_rate>10</update_rate>
      <ray>
        <scan>
          <horizontal>
            <samples>720</samples>
            <resolution>1</resolution>
            <min_angle>-3.14</min_angle>
            <max_angle>3.14</max_angle>
          </horizontal>
        </scan>
        <range>
          <min>0.12</min>
          <max>10.0</max>
          <resolution>0.01</resolution>
        </range>
        <noise>
          <type>gaussian</type>
          <mean>0.0</mean>
          <stddev>0.01</stddev>
        </noise>
      </ray>
      <plugin name='laser_controller' filename='libgazebo_ros_ray_sensor.so'>
        <ros>
          <argument>~/out:=scan</argument>
        </ros>
        <output_type>sensor_msgs/LaserScan</output_type>
        <frame_name>lidar_link</frame_name>
      </plugin>
    </sensor>
  </gazebo>

  <!-- Differential Drive Plugin -->
  <gazebo>
    <plugin name="diff_drive" filename="libgazebo_ros_diff_drive.so">
      <ros>
        <namespace>/</namespace>
        <remapping>cmd_vel:=/cmd_vel</remapping>
        <remapping>odom:=/odom</remapping>
      </ros>

      <left_joint>left_wheel_joint</left_joint>
      <right_joint>right_wheel_joint</right_joint>
      <wheel_separation>0.48</wheel_separation>
      <wheel_diameter>0.30</wheel_diameter>

      <commandTopic>cmd_vel</commandTopic>
      <odometryTopic>odom</odometryTopic>
      <odometryFrame>odom</odometryFrame>
      <robotBaseFrame>base_footprint</robotBaseFrame>

      <publishOdom>true</publishOdom>
      <publishWheelTF>true</publishWheelTF>
      <publish_odom_tf>true</publish_odom_tf>
      <publishTF>true</publishTF>
      <updateRate>50.0</updateRate>
    </plugin>
  </gazebo>

  <!-- Gazebo Materials -->
  <gazebo reference="base_link"><material>Gazebo/Blue</material></gazebo>
  <gazebo reference="right_wheel_link"><material>Gazebo/Black</material></gazebo>
  <gazebo reference="left_wheel_link"><material>Gazebo/Black</material></gazebo>
  <gazebo reference="caster_wheel"><material>Gazebo/Grey</material></gazebo>
  <gazebo reference="lidar_link"><material>Gazebo/White</material></gazebo>

</robot>
